Workbook
Name CurrentYear: #REF!
Name CurrentYear: #REF!
Name dfsf: #REF!
Name dfsf: #REF!
Name dfsf: #REF!
Name dfsf: #REF!
Name dfsf: #REF!
Name dfsf: #REF!
Name dfsf: #REF!
Name fromyear: #REF!
Name fromyear: #REF!
Name grow: #REF!
Name grow: #REF!
Name grow: #REF!
Name population_and_dependency_ratios: '10. Population Growth'!#REF!
Name population_and_dependency_ratios: '11. Pop, by Age Group'!#REF!
Name sdf: #REF!
Name sdf: #REF!
Name sdf: #REF!
Name sdf: #REF!
Name sdf: #REF!
Name sdf: #REF!
Name sdf: #REF!
Name TABLE3: #REF!
Name TABLE3: #REF!
Name TABLE3: #REF!
Name TABLE3: #REF!
Name TABLE3: #REF!
Name TABLE3: #REF!
Name TABLE3: #REF!
Name toyear: #REF!
Name toyear: #REF!

Sheet Contents
A1: This file is CBO’s February 2026 publication The Long-Term Budget Outlook Data: 2026 to 2056.
A2: www.cbo.gov/publication/62044
A4: In lieu of publishing a report providing the Congressional Budget Office's latest long-term budget outlook, the agency is publishing the data that it would have presented in that report.
A6: CBO's long-term budget projections, referred to as the extended baseline, follow the agency’s 10-year baseline projections and then extend most of the concepts underlying those projections for an additional 20 years.
A8: These long-term budget projections are based on CBO's demographic projections published on January 7, 2026, its economic and 10-year budget projections published on February 11, 2026, and the agency's 30-year budget projections that extend those earlier projections. They do not account for any budgetary or economic effects of the Supreme Court’s February 20, 2026, ruling on tariffs (Learning Res., Inc. v. Trump, Nos. 24-1287, 25-250, slip op. (S. Ct. Feb. 20, 2026)).
A10: Contents
A11: =HYPERLINK("#'1. Key Projections'!A1",TRIM(SUBSTITUTE(SUBSTITUTE('1. Key Projections'!A5,CHAR(10)," "),CHAR(13)," "))) -> 1. Key Projections for Selected Years
A12: =HYPERLINK("#'1a. Key Proj, Supp Data'!A1",TRIM(SUBSTITUTE(SUBSTITUTE('1a. Key Proj, Supp Data'!A5,CHAR(10)," "),CHAR(13)," "))) -> 1a. Projections of Revenues and Outlays for Social Security and Medicare, 2026 to 2056
A13: =HYPERLINK("#'2. Debt and Deficits'!A1",TRIM(SUBSTITUTE(SUBSTITUTE('2. Debt and Deficits'!A5,CHAR(10)," "),CHAR(13)," "))) -> 2. Debt and Deficits
A14: =HYPERLINK("#'3. Outlays and Revenues'!A1",TRIM(SUBSTITUTE(SUBSTITUTE('3. Outlays and Revenues'!A5,CHAR(10)," "),CHAR(13)," "))) -> 3. Total Outlays and Revenues
A15: =HYPERLINK("#'4. Outlays, by Category'!A1",TRIM(SUBSTITUTE(SUBSTITUTE('4. Outlays, by Category'!A5,CHAR(10)," "),CHAR(13)," "))) -> 4. Outlays, by Category
A16: =HYPERLINK("#'5. Composition of Outlays'!A1",TRIM(SUBSTITUTE(SUBSTITUTE('5. Composition of Outlays'!A5,CHAR(10)," "),CHAR(13)," "))) -> 5. Composition of Outlays, 2026 and 2056
A17: =HYPERLINK("#'6. Outlays for Health Care'!A1",TRIM(SUBSTITUTE(SUBSTITUTE('6. Outlays for Health Care'!A5,CHAR(10)," "),CHAR(13)," "))) -> 6. Composition of Outlays for the Major Health Care Programs
A18: =HYPERLINK("#'7. Growth in Outlays'!A1",TRIM(SUBSTITUTE(SUBSTITUTE('7. Growth in Outlays'!A5,CHAR(10)," "),CHAR(13)," "))) -> 7. Composition of Growth in Outlays for the Major Health Care Programs and Social Security, 2026 to 2056
A19: =HYPERLINK("#'8. Revenues, by Source'!A1",TRIM(SUBSTITUTE(SUBSTITUTE('8. Revenues, by Source'!A5,CHAR(10)," "),CHAR(13)," "))) -> 8. Revenues, by Source
A20: =HYPERLINK("#'9. Income Tax Rates'!A1",TRIM(SUBSTITUTE(SUBSTITUTE('9. Income Tax Rates'!A5,CHAR(10)," "),CHAR(13)," "))) -> 9. Shares of Income Taxed at Different Rates Under the Individual Income Tax System
A21: =HYPERLINK("#'10. Population Growth'!A1",TRIM(SUBSTITUTE(SUBSTITUTE('10. Population Growth'!A5,CHAR(10)," "),CHAR(13)," "))) -> 10. Population Growth and Contributing Factors
A22: =HYPERLINK("#'11. Pop, by Age Group'!A1",TRIM(SUBSTITUTE(SUBSTITUTE('11. Pop, by Age Group'!A5,CHAR(10)," "),CHAR(13)," "))) -> 11. Population, by Age Group
A23: =HYPERLINK("#'12. Key Econ Variables'!A1",TRIM(SUBSTITUTE(SUBSTITUTE('12. Key Econ Variables'!A5,CHAR(10)," "),CHAR(13)," "))) -> 12. Average Annual Values for Key Economic Variables That Underlie CBO’s Extended Baseline Projections
A24: =HYPERLINK("#'13. Add''l Econ Variables'!A1",TRIM(SUBSTITUTE(SUBSTITUTE('13. Add''l Econ Variables'!A5,CHAR(10)," "),CHAR(13)," "))) -> 13. Average Annual Values for Additional Economic Variables That Underlie CBO’s Extended Baseline Projections
A25: =HYPERLINK("#'14. GDP Growth'!A1",TRIM(SUBSTITUTE(SUBSTITUTE('14. GDP Growth'!A5,CHAR(10)," "),CHAR(13)," "))) -> 14. Average Annual Growth of Real Potential GDP and Its Components
A26: =HYPERLINK("#'15. Interest Rates'!A1",TRIM(SUBSTITUTE(SUBSTITUTE('15. Interest Rates'!A5,CHAR(10)," "),CHAR(13)," "))) -> 15. Average Interest Rates on Federal Debt and on 10-year Treasury Notes
A27: =HYPERLINK("#'16. 2025&2026 Econ Proj'!A1",TRIM(SUBSTITUTE(SUBSTITUTE('16. 2025&2026 Econ Proj'!A5,CHAR(10)," "),CHAR(13)," "))) -> 16. CBO’s 2025 and 2026 Projections of Selected Economic Variables
A28: =HYPERLINK("#'17. 2025&2026 Lbr Force Proj'!A1",TRIM(SUBSTITUTE(SUBSTITUTE('17. 2025&2026 Lbr Force Proj'!A5,CHAR(10)," "),CHAR(13)," "))) -> 17. CBO’s 2025 and 2026 Projections of the Labor Force
A29: =HYPERLINK("#'18. 2025&2026 Real GDP Proj'!A1",TRIM(SUBSTITUTE(SUBSTITUTE('18. 2025&2026 Real GDP Proj'!A5,CHAR(10)," "),CHAR(13)," "))) -> 18. CBO’s 2025 and 2026 Projections of Real Potential GDP
A30: =HYPERLINK("#'19. 2025&2026 Int Rate Proj'!A1",TRIM(SUBSTITUTE(SUBSTITUTE('19. 2025&2026 Int Rate Proj'!A5,CHAR(10)," "),CHAR(13)," "))) -> 19. CBO’s 2025 and 2026 Projections of Interest Rates on 10-Year Treasury Notes
A31: =HYPERLINK("#'20. 2025&2026 Proj, Select Yrs'!A1",TRIM(SUBSTITUTE(SUBSTITUTE('20. 2025&2026 Proj, Select Yrs'!A5,CHAR(10)," "),CHAR(13)," "))) -> 20. CBO’s 2025 and 2026 Projections of Revenues, Outlays, Deficits, and Federal Debt Held by the Public in Selected Years
A32: =HYPERLINK("#'21. 2025&2026 Def & Debt'!A1",TRIM(SUBSTITUTE(SUBSTITUTE('21. 2025&2026 Def & Debt'!A5,CHAR(10)," "),CHAR(13)," "))) -> 21. CBO’s 2025 and 2026 Projections of Deficits and Federal Debt Held by the Public
A33: =HYPERLINK("#'22. 2025&2026 Outlay Proj'!A1",TRIM(SUBSTITUTE(SUBSTITUTE('22. 2025&2026 Outlay Proj'!A5,CHAR(10)," "),CHAR(13)," "))) -> 22. CBO’s 2025 and 2026 Projections of Outlays
A34: =HYPERLINK("#'23. 2025&2026 Rev Proj'!A1",TRIM(SUBSTITUTE(SUBSTITUTE('23. 2025&2026 Rev Proj'!A5,CHAR(10)," "),CHAR(13)," "))) -> 23. CBO’s 2025 and 2026 Projections of Revenues

Sheet 1. Key Projections
A1: This file is CBO’s February 2026 publication The Long-Term Budget Outlook Data: 2026 to 2056.
A2: www.cbo.gov/publication/62044
A5: 1. Key Projections for Selected Years
A6: Percentage of GDP
B8: 2026 | C8: 2036 | D8: 2046 | E8: 2056
A9: Revenues
A10: Individual income taxes | B10: 8.624 | C10: 9.096 | D10: 9.632 | E10: 10.115
A11: Payroll taxes | B11: 5.722 | C11: 5.707 | D11: 5.683 | E11: 5.66
A12: Corporate income taxes | B12: 1.266 | C12: 1.232 | D12: 1.284 | E12: 1.31
A13: Customs dutiesa | B13: 1.311 | C13: 0.861 | D13: 0.751 | E13: 0.674
A14: Otherb | B14: 0.617 | C14: 0.873 | D14: 0.978 | E14: 1.039
A15: Total | B15: 17.541 | C15: 17.77 | D15: 18.328 | E15: 18.798
A17: Outlays
A18: Mandatory
A19: Social Security | B19: 5.222 | C19: 5.88 | D19: 5.774 | E19: 5.991
A20: Major health care programsc | B20: 5.982 | C20: 6.669 | D20: 7.559 | E20: 8.085
A21: Other | B21: 2.994 | C21: 2.497 | D21: 2.378 | E21: 2.285
A22: Subtotal | B22: 14.198 | C22: 15.045 | D22: 15.712 | E22: 16.361
A23: Discretionary | B23: 5.894 | C23: 4.804 | D23: 4.641 | E23: 4.641
A24: Net interest | B24: 3.257 | C24: 4.591 | D24: 5.676 | E24: 6.93
A25: Total | B25: 23.348 | C25: 24.439 | D25: 26.029 | E25: 27.932
A26: Total deficit (-)d | B26: -5.807 | C26: -6.669 | D26: -7.701 | E26: -9.134
A27: Primary deficit (-)d,e | B27: -2.551 | C27: -2.079 | D27: -2.025 | E27: -2.204
A28: Debt held by the public at the end of the period | B28: 100.605 | C28: 120.223 | D28: 144.497 | E28: 175.076
A29: Addendum:
A30: Social Security
A31: Revenuesf | B31: 4.442 | C31: 4.451 | D31: 4.415 | E31: 4.388
A32: Outlaysg | B32: 5.222 | C32: 5.88 | D32: 5.774 | E32: 5.991
A33: Contribution to the deficit (-)d,h | B33: -0.78 | C33: -1.429 | D33: -1.36 | E33: -1.602
A34: Medicare
A35: Revenuesf | B35: 1.457 | C35: 1.528 | D35: 1.57 | E35: 1.625
A36: Outlaysg | B36: 4.034 | C36: 5.183 | D36: 6.249 | E36: 6.887
A37: Offsetting receipts | B37: -0.702 | C37: -0.966 | D37: -1.248 | E37: -1.433
A38: Contribution to the deficit (-)d,h | B38: -1.875 | C38: -2.689 | D38: -3.431 | E38: -3.828
A39: GDP at the end of the period (trillions of dollars) | B39: 31.902 | C39: 46.712 | D39: 67.459 | E39: 95.69
A42: Data Source: Congressional Budget Office.
A43: This table provides information specified in section 3111 of S. Con. Res. 11, the Concurrent Resolution on the Budget for Fiscal Year 2016.
A44: When October 1 (the first day of the fiscal year) falls on a weekend, certain payments that ordinarily would have been made on that day are instead made at the end of September and thus are shifted into the previous fiscal year. All projections have been adjusted to exclude the effects of those timing shifts.
A45: a. Values do not account for effects of the Supreme Court's February 20, 2026, ruling on tariffs.
A46: b. Consists of excise taxes, remittances to the Treasury from the Federal Reserve System, customs duties, estate and gift taxes, and miscellaneous fees and fines
...

Sheet 1a. Key Proj, Supp Data
A1: This file is CBO’s February 2026 publication The Long-Term Budget Outlook Data: 2026 to 2056.
A2: www.cbo.gov/publication/62044
A5: 1a. Projections of Revenues and Outlays for Social Security and Medicare, 2026 to 2056
A6: Percentage of GDP
B7: Social Security | E7: Medicare
B8: Revenuesa | C8: Outlaysb | E8: Revenuesa | F8: Outlaysb | G8: Offsetting receipts
A9: 2026 | B9: 4.442 | C9: 5.222 | E9: 1.457 | F9: 4.034 | G9: -0.702
A10: 2027 | B10: 4.427 | C10: 5.31 | E10: 1.464 | F10: 4.123 | G10: -0.701
A11: 2028 | B11: 4.421 | C11: 5.409 | E11: 1.473 | F11: 4.188 | G11: -0.718
A12: 2029 | B12: 4.437 | C12: 5.494 | E12: 1.482 | F12: 4.309 | G12: -0.739
A13: 2030 | B13: 4.449 | C13: 5.57 | E13: 1.492 | F13: 4.409 | G13: -0.782
A14: 2031 | B14: 4.455 | C14: 5.642 | E14: 1.498 | F14: 4.516 | G14: -0.814
A15: 2032 | B15: 4.457 | C15: 5.706 | E15: 1.504 | F15: 4.634 | G15: -0.845
A16: 2033 | B16: 4.458 | C16: 5.763 | E16: 1.51 | F16: 4.799 | G16: -0.88
A17: 2034 | B17: 4.455 | C17: 5.809 | E17: 1.516 | F17: 4.946 | G17: -0.908
A18: 2035 | B18: 4.453 | C18: 5.847 | E18: 1.522 | F18: 5.066 | G18: -0.938
A19: 2036 | B19: 4.451 | C19: 5.88 | E19: 1.528 | F19: 5.183 | G19: -0.966
A20: 2037 | B20: 4.448 | C20: 5.869 | E20: 1.533 | F20: 5.304 | G20: -1.006
... A39: 2056 | B39: 4.388 | C39: 5.991 | E39: 1.625 | F39: 6.887 | G39: -1.433
A41: Data source: Congressional Budget Office.
A42: a. Includes payroll taxes other than those paid by the federal government on behalf of its employees; those payments are intragovernmental transactions. Also includes income taxes paid on Social Security benefits, which are credited to the Social Security trust funds.
A43: b. Does not include outlays related to the administration of the program, which are discretionary. For Social Security, outlays do not include intragovernmental offsetting receipts stemming from the employer’s share of payroll taxes paid to the Social Security trust funds by federal agencies on behalf of their employees.
A46: Back to Table of Contents

Sheet 2. Debt and Deficits
A1: This file is CBO’s February 2026 publication The Long-Term Budget Outlook Data: 2026 to 2056.
A2: www.cbo.gov/publication/62044
A5: 2. Debt and Deficits
A6: Percentage of GDP
B8: Primary deficit or surplus (-) | C8: Net interest outlays | D8: Total deficit or surplus (-) | F8: Federal debt held by the public
A9: 1940 | B9: 2.085 | C9: 0.915 | D9: 3 | F9: 43.6
A10: 1941 | B10: 3.488 | C10: 0.812 | D10: 4.3 | F10: 41.5
A11: 1942 | B11: 13.188 | C11: 0.712 | D11: 13.9 | F11: 45.9
A12: 1943 | B12: 28.772 | C12: 0.828 | D12: 29.6 | F12: 69.2
A13: 1944 | B13: 21.162 | C13: 1.038 | D13: 22.2 | F13: 86.4
A14: 1945 | B14: 19.625 | C14: 1.375 | D14: 21 | F14: 103.9
A15: 1946 | B15: 5.197 | C15: 1.803 | D15: 7 | F15: 106.1
A16: 1947 | B16: -3.46 | C16: 1.76 | D16: -1.7 | F16: 93.9
A17: 1948 | B17: -6.158 | C17: 1.658 | D17: -4.5 | F17: 82.6
A18: 1949 | B18: -1.836 | C18: 1.636 | D18: -0.2 | F18: 77.5
A19: 1950 | B19: -0.608 | C19: 1.727 | D19: 1.119 | F19: 78.594
A20: 1951 | B20: -3.292 | C20: 1.426 | D20: -1.866 | F20: 65.533
... A94: 2025 | B94: 2.656 | C94: 3.195 | D94: 5.847 | F94: 99.375
A95: 2026 | B95: 2.551 | C95: 3.257 | D95: 5.807 | F95: 100.605 | G95: Projected
A96: 2027 | B96: 2.34 | C96: 3.325 | D96: 5.665 | F96: 102.069
A97: 2028 | B97: 2.13 | C97: 3.513 | D97: 5.643 | F97: 104.116
A98: 2029 | B98: 2.274 | C98: 3.678 | D98: 5.952 | F98: 105.811
A99: 2030 | B99: 2.056 | C99: 3.829 | D99: 5.886 | F99: 107.726
A100: 2031 | B100: 1.9 | C100: 3.989 | D100: 5.889 | F100: 109.573
A101: 2032 | B101: 1.909 | C101: 4.147 | D101: 6.057 | F101: 111.535
A102: 2033 | B102: 1.987 | C102: 4.269 | D102: 6.256 | F102: 113.992
A103: 2034 | B103: 2.081 | C103: 4.389 | D103: 6.47 | F103: 116.186
A104: 2035 | B104: 2.084 | C104: 4.486 | D104: 6.57 | F104: 117.977
A105: 2036 | B105: 2.079 | C105: 4.591 | D105: 6.669 | F105: 120.209
A106: 2037 | B106: 2.022 | C106: 4.687 | D106: 6.709 | F106: 122.449
A107: 2038 | B107: 2.023 | C107: 4.788 | D107: 6.81 | F107: 124.742
... A125: 2056 | B125: 2.204 | C125: 6.93 | D125: 9.134 | F125: 175.076
A127: Data source: Congressional Budget Office, Office of Management and Budget.
A128: Primary deficits exclude net outlays for interest. In this table, deficits were calculated by subtracting revenues from outlays; thus, positive values indicate deficits, and negative values indicate surpluses, which occur when revenues exceed outlays.
A131: Back to Table of Contents

Sheet 3. Outlays and Revenues
A1: This file is CBO’s February 2026 publication The Long-Term Budget Outlook Data: 2026 to 2056.
A2: www.cbo.gov/publication/62044
A5: 3. Total Outlays and Revenues
A6: Percentage of GDP
B8: Revenues | C8: Outlays
A9: 2011 | B9: 14.893 | C9: 23.296
A10: 2012 | B10: 15.208 | C10: 21.891
A11: 2013 | B11: 16.63 | C11: 20.703
A12: 2014 | B12: 17.337 | C12: 20.119
A13: 2015 | B13: 17.892 | C13: 20.325
A14: 2016 | B14: 17.531 | C14: 20.667
A15: 2017 | B15: 17.116 | C15: 20.55
A16: 2018 | B16: 16.294 | C16: 20.106
A17: 2019 | B17: 16.271 | C17: 20.891
A18: 2020 | B18: 16.034 | C18: 30.715
A19: 2021 | B19: 17.562 | C19: 29.606
A20: 2022 | B20: 19.156 | C20: 24.538
... A23: 2025 | B23: 17.241 | C23: 23.088
A24: 2026 | B24: 17.541 | C24: 23.348 | D24: Projected
A25: 2027 | B25: 17.665 | C25: 23.33
A26: 2028 | B26: 17.514 | C26: 23.157
A27: 2029 | B27: 17.55 | C27: 23.502
A28: 2030 | B28: 17.638 | C28: 23.524
A29: 2031 | B29: 17.699 | C29: 23.588
A30: 2032 | B30: 17.702 | C30: 23.759
A31: 2033 | B31: 17.685 | C31: 23.941
A32: 2034 | B32: 17.681 | C32: 24.151
A33: 2035 | B33: 17.711 | C33: 24.28
A34: 2036 | B34: 17.77 | C34: 24.439
A35: 2037 | B35: 17.826 | C35: 24.535
A36: 2038 | B36: 17.88 | C36: 24.691
... A54: 2056 | B54: 18.798 | C54: 27.932
A55: Average, 1976 to 2025 | B55: 17.317 | C55: 21.153
A57: Data sources: Congressional Budget Office, Office of Management and Budget.
A60: Back to Table of Contents

Sheet 4. Outlays, by Category
A1: This file is CBO’s February 2026 publication The Long-Term Budget Outlook Data: 2026 to 2056.
A2: www.cbo.gov/publication/62044
A5: 4. Outlays, by Category
A6: Percentage of GDP
C8: Mandatory
B9: Total | C9: Major health care programsa | D9: Social Security | E9: Otherb | F9: Discretionary | G9: Net interest
A10: 2011 | B10: 23.296 | C10: 4.937 | D10: 4.687 | E10: 3.475 | F10: 8.71 | G10: 1.487
A11: 2012 | B11: 21.891 | C11: 4.505 | D11: 4.766 | E11: 3.333 | F11: 7.919 | G11: 1.368
A12: 2013 | B12: 20.703 | C12: 4.6 | D12: 4.841 | E12: 2.734 | F12: 7.205 | G12: 1.324
A13: 2014 | B13: 20.119 | C13: 4.768 | D13: 4.848 | E13: 2.425 | F13: 6.764 | G13: 1.314
A14: 2015 | B14: 20.325 | C14: 5.156 | D14: 4.855 | E14: 2.632 | F14: 6.453 | G14: 1.229
A15: 2016 | B15: 20.667 | C15: 5.432 | D15: 4.883 | E15: 2.706 | F15: 6.358 | G15: 1.288
A16: 2017 | B16: 20.55 | C16: 5.318 | D16: 4.847 | E16: 2.834 | F16: 6.195 | G16: 1.355
A17: 2018 | B17: 20.106 | C17: 5.077 | D17: 4.805 | E17: 2.461 | F17: 6.173 | G17: 1.59
A18: 2019 | B18: 20.891 | C18: 5.292 | D18: 4.879 | E18: 2.672 | F18: 6.286 | G18: 1.762
A19: 2020 | B19: 30.715 | C19: 6.1 | D19: 5.108 | E19: 10.258 | F19: 7.629 | G19: 1.619
A20: 2021 | B20: 29.606 | C20: 5.629 | D20: 4.899 | E20: 10.449 | F20: 7.101 | G20: 1.529
A21: 2022 | B21: 24.538 | C21: 5.64 | D21: 4.743 | E21: 5.783 | F21: 6.511 | G21: 1.861
... A24: 2025 | B24: 23.088 | C24: 5.992 | D24: 5.188 | E24: 2.549 | F24: 6.167 | G24: 3.195
A25: 2026 | B25: 23.348 | C25: 5.982 | D25: 5.222 | E25: 2.994 | F25: 5.894 | G25: 3.257 | H25: Projected
A26: 2027 | B26: 23.33 | C26: 5.959 | D26: 5.31 | E26: 3.088 | F26: 5.648 | G26: 3.325
A27: 2028 | B27: 23.157 | C27: 5.955 | D27: 5.409 | E27: 2.732 | F27: 5.548 | G27: 3.513
A28: 2029 | B28: 23.502 | C28: 5.998 | D28: 5.494 | E28: 2.905 | F28: 5.426 | G28: 3.678
A29: 2030 | B29: 23.524 | C29: 6.038 | D29: 5.57 | E29: 2.767 | F29: 5.319 | G29: 3.829
A30: 2031 | B30: 23.588 | C30: 6.099 | D30: 5.642 | E30: 2.642 | F30: 5.216 | G30: 3.989
A31: 2032 | B31: 23.759 | C31: 6.195 | D31: 5.706 | E31: 2.587 | F31: 5.123 | G31: 4.147
A32: 2033 | B32: 23.941 | C32: 6.337 | D32: 5.763 | E32: 2.536 | F32: 5.035 | G32: 4.269
A33: 2034 | B33: 24.151 | C33: 6.463 | D33: 5.809 | E33: 2.541 | F33: 4.9497 | G33: 4.389
A34: 2035 | B34: 24.28 | C34: 6.564 | D34: 5.847 | E34: 2.509 | F34: 4.874 | G34: 4.486
A35: 2036 | B35: 24.439 | C35: 6.669 | D35: 5.88 | E35: 2.497 | F35: 4.804 | G35: 4.591
A36: 2037 | B36: 24.535 | C36: 6.758 | D36: 5.869 | E36: 2.484 | F36: 4.738 | G36: 4.687
A37: 2038 | B37: 24.691 | C37: 6.863 | D37: 5.878 | E37: 2.473 | F37: 4.689 | G37: 4.788
... A55: 2056 | B55: 27.932 | C55: 8.085 | D55: 5.991 | E55: 2.285 | F55: 4.641 | G55: 6.93
A58: Data source: Congressional Budget Office.
A59: a. Consists of outlays for Medicare (net of premiums and other offsetting receipts), Medicaid, and the Children’s Health Insurance Program, as well as premium tax credits for health insurance purchased through the marketplaces established under the Affordable Care Act and related spending.
A60: b. Consists of all mandatory spending other than that for Social Security and the major health care programs. “Other mandatory” includes the refundable portions of the earned income tax credit, the child tax credit, and the American Opportunity Tax Credit.
A63: Back to Table of Contents

Sheet 5. Composition of Outlays
A1: This file is CBO’s February 2026 publication The Long-Term Budget Outlook Data: 2026 to 2056.
A2: www.cbo.gov/publication/62044
A5: 5. Composition of Outlays, 2026 and 2056
A6: Percent
B8: Total outlays | E8: Noninterest outlays
B9: Net interest | C9: Noninterest | E9: Discretionary | F9: Other mandatorya | G9: Social Security | H9: Major health care programsb
A10: 2026 | B10: 13.949 | C10: 86.051 | E10: 29.336 | F10: 14.9 | G10: 25.991 | H10: 29.773
A11: 2056 | B11: 24.811 | C11: 75.189 | E11: 22.098 | F11: 10.882 | G11: 28.524 | H11: 38.495
A14: Data source: Congressional Budget Office
A15: a. Outlays for other mandatory spending consists of all mandatory spending other than that for Social Security and the major health care programs. “Other mandatory” includes the refundable portions of the earned income tax credit, the child tax credit, and the American Opportunity Tax Credit.
A16: b. Outlays for major health care programs consist of outlays for Medicare (net of premiums and other offsetting receipts), Medicaid, and the Children’s Health Insurance Program, as well as premium tax credits for health insurance purchased through the marketplaces established under the Affordable Care Act and related spending.
A19: Back to Table of Contents

Sheet 6. Outlays for Health Care
A1: This file is CBO’s February 2026 publication The Long-Term Budget Outlook Data: 2026 to 2056.
A2: www.cbo.gov/publication/62044
A5: 6. Composition of Outlays for the Major Health Care Programs
A6: Percentage of GDP
B8: Medicarea | C8: Medicaid, CHIP, and premium tax credits and related spendingb
A9: 2011 | B9: 3.103 | C9: 1.834
A10: 2012 | B10: 2.893 | C10: 1.613
A11: 2013 | B11: 2.947 | C11: 1.653
A12: 2014 | B12: 2.899 | C12: 1.869
A13: 2015 | B13: 2.972 | C13: 2.184
A14: 2016 | B14: 3.156 | C14: 2.276
A15: 2017 | B15: 3.052 | C15: 2.266
A16: 2018 | B16: 2.847 | C16: 2.23
A17: 2019 | B17: 3.025 | C17: 2.267
A18: 2020 | B18: 3.604 | C18: 2.497
A19: 2021 | B19: 2.989 | C19: 2.64
A20: 2022 | B20: 2.923 | C20: 2.717
... A23: 2025 | B23: 3.256 | C23: 2.742
A24: 2026 | B24: 3.332 | C24: 2.64997 | D24: Projected
A25: 2027 | B25: 3.422 | C25: 2.537
A26: 2028 | B26: 3.47 | C26: 2.485
A27: 2029 | B27: 3.57 | C27: 2.428
A28: 2030 | B28: 3.627 | C28: 2.411
A29: 2031 | B29: 3.702 | C29: 2.397
A30: 2032 | B30: 3.789 | C30: 2.406
A31: 2033 | B31: 3.919 | C31: 2.418
A32: 2034 | B32: 4.037 | C32: 2.426
A33: 2035 | B33: 4.128 | C33: 2.436
A34: 2036 | B34: 4.216 | C34: 2.452
A35: 2037 | B35: 4.298 | C35: 2.459
A36: 2038 | B36: 4.392 | C36: 2.471
... A54: 2056 | B54: 5.454 | C54: 2.631
A57: Data source: Congressional Budget Office.
A58: CHIP = Children’s Health Insurance Program.
A59: a. Net of premiums and other offsetting receipts.
A60: b. Premium tax credits subsidize the purchase of health insurance through the marketplaces established under the Affordable Care Act. Related spending is spending to subsidize health insurance provided through the Basic Health Program and to stabilize premiums for health insurance purchased by individuals and small employers.
A63: Back to Table of Contents

Sheet 7. Growth in Outlays
A1: This file is CBO’s February 2026 publication The Long-Term Budget Outlook Data: 2026 to 2056.
A2: www.cbo.gov/publication/62044
A5: 7. Composition of Growth in Outlays for the Major Health Care Programs and Social Security, 2026 to 2056
A6: Percentage of GDP
B8: Outlays without the effects of additional cost growth or aging of the population | C8: Aging of the population | D8: Additional cost growth | E8: Total
A9: Major health care programs
A10: 2026 | B10: 6.684 | C10: n.a. | D10: n.a. | E10: 6.684
A11: 2056 | B11: 6.476 | C11: 1.373 | D11: 1.669 | E11: 9.518
A13: Social Security
A14: 2026 | B14: 5.222 | C14: n.a. | D14: n.a. | E14: 5.222
A15: 2056 | B15: 4.78 | C15: 1.211 | D15: n.a. | E15: 5.991
A18: Data source: Congressional Budget Office.
A20: The spending on the major health care programs examined here consists of gross spending on Medicare (which does not account for premiums or other offsetting receipts), Medicaid, the Children’s Health Insurance Program, and premium tax credits and related spending. Premium tax credits subsidize the purchase of health insurance through the marketplaces established under the Affordable Care Act. Related spending is spending to subsidize health insurance provided through the Basic Health Program and to stabilize premiums for health insurance purchased by individuals and small employers.
A21: Additional cost growth is the amount by which the growth rate of nominal health care spending per person (adjusted to remove the effects of demographic changes) exceeds the growth rate of potential GDP per person. Potential GDP is the maximum sustainable output of the economy
A23: n.a. = not applicable.
A26: Back to Table of Contents

Sheet 8. Revenues, by Source
A1: This file is CBO’s February 2026 publication The Long-Term Budget Outlook Data: 2026 to 2056.
A2: www.cbo.gov/publication/62044
A5: 8. Revenues, by Source
A6: Percentage of GDP
B8: Total | C8: Individual income taxes | D8: Payroll taxes | E8: Corporate income taxes | F8: Customs dutiesa | G8: Otherb
A9: 2011 | B9: 14.893 | C9: 7.057 | D9: 5.294 | E9: 1.171 | F9: 0.191 | G9: 1.181
A10: 2012 | B10: 15.208 | C10: 7.028 | D10: 5.247 | E10: 1.504 | F10: 0.188 | G10: 1.241
A11: 2013 | B11: 16.63 | C11: 7.888 | D11: 5.68 | E11: 1.639 | F11: 0.191 | G11: 1.232
A12: 2014 | B12: 17.337 | C12: 8.002 | D12: 5.872 | E12: 1.84 | F12: 0.195 | G12: 1.428
A13: 2015 | B13: 17.892 | C13: 8.483 | D13: 5.865 | E13: 1.893 | F13: 0.193 | G13: 1.459
A14: 2016 | B14: 17.531 | C14: 8.294 | D14: 5.982 | E14: 1.607 | F14: 0.187 | G14: 1.461
A15: 2017 | B15: 17.116 | C15: 8.192 | D15: 5.997 | E15: 1.533 | F15: 0.178 | G15: 1.216
A16: 2018 | B16: 16.294 | C16: 8.238 | D16: 5.729 | E16: 1.002 | F16: 0.202 | G16: 1.124
A17: 2019 | B17: 16.271 | C17: 8.07 | D17: 5.84 | E17: 1.082 | F17: 0.333 | G17: 0.946
A18: 2020 | B18: 16.034 | C18: 7.539 | D18: 6.139 | E18: 0.993 | F18: 0.321 | G18: 1.041
A19: 2021 | B19: 17.562 | C19: 8.872 | D19: 5.703 | E19: 1.614 | F19: 0.347 | G19: 1.028
A20: 2022 | B20: 19.156 | C20: 10.296 | D20: 5.803 | E20: 1.662 | F20: 0.391 | G20: 1.005
... A23: 2025 | B23: 17.241 | C23: 8.748 | D23: 5.758 | E23: 1.489 | F23: 0.642 | G23: 0.604
A24: 2026 | B24: 17.541 | C24: 8.624 | D24: 5.722 | E24: 1.266 | F24: 1.311 | G24: 0.617 | H24: Projected
A25: 2027 | B25: 17.665 | C25: 8.846 | D25: 5.693 | E25: 1.259 | F25: 1.264 | G25: 0.604
A26: 2028 | B26: 17.514 | C26: 8.781 | D26: 5.683 | E26: 1.248 | F26: 1.222 | G26: 0.58
A27: 2029 | B27: 17.55 | C27: 8.868 | D27: 5.689 | E27: 1.254 | F27: 1.159 | G27: 0.58
A28: 2030 | B28: 17.638 | C28: 8.93 | D28: 5.701 | E28: 1.277 | F28: 1.103 | G28: 0.628
A29: 2031 | B29: 17.699 | C29: 8.917 | D29: 5.71 | E29: 1.271 | F29: 1.044 | G29: 0.756
A30: 2032 | B30: 17.702 | C30: 8.924 | D30: 5.714 | E30: 1.266 | F30: 0.967 | G30: 0.83
A31: 2033 | B31: 17.685 | C31: 8.957 | D31: 5.715 | E31: 1.258 | F31: 0.915 | G31: 0.839
A32: 2034 | B32: 17.681 | C32: 8.998 | D32: 5.712 | E32: 1.243 | F32: 0.88 | G32: 0.848
A33: 2035 | B33: 17.711 | C33: 9.046 | D33: 5.71 | E33: 1.226 | F33: 0.867 | G33: 0.862
A34: 2036 | B34: 17.77 | C34: 9.096 | D34: 5.707 | E34: 1.232 | F34: 0.861 | G34: 0.873
A35: 2037 | B35: 17.826 | C35: 9.154 | D35: 5.703 | E35: 1.229 | F35: 0.851 | G35: 0.89
A36: 2038 | B36: 17.88 | C36: 9.221 | D36: 5.701 | E36: 1.227 | F36: 0.839 | G36: 0.893
... A54: 2056 | B54: 18.798 | C54: 10.115 | D54: 5.66 | E54: 1.31 | F54: 0.674 | G54: 1.039
A57: Data source: Congressional Budget Office.
A59: a. Values do not account for effects of the Supreme Court's February 20, 2026, ruling on tariffs.
A60: b. “Other” revenues consist of excise taxes, remittances from the Federal Reserve System, estate and gift taxes, and miscellaneous fees and fines.
A63: Back to Table of Contents

Sheet 9. Income Tax Rates
A1: This file is CBO’s February 2026 publication The Long-Term Budget Outlook Data: 2026 to 2056.
A2: www.cbo.gov/publication/62044
A5: 9. Shares of Income Taxed at Different Rates Under the Individual Income Tax System
A6: Percent
B8: Income tax rate
B9: 0 | C9: 10 to 15 percent | D9: 20 to 35 percent | E9: 37 percent
A10: 2026 | B10: 25 | C10: 36 | D10: 31 | E10: 8
A11: 2056 | B11: 18 | C11: 32 | D11: 39 | E11: 11
A14: Data source: Congressional Budget Office.
A15: Income refers to adjusted gross income—that is, income from all sources not specifically excluded by the tax code, minus certain deductions. The income tax rate is the statutory rate specified under the individual income tax system. The lowest statutory tax rate is zero (because of deductions and exemptions).
A18: Back to Table of Contents

Sheet 10. Population Growth
A1: This file is CBO’s February 2026 publication The Long-Term Budget Outlook Data: 2026 to 2056.
A2: www.cbo.gov/publication/62044
A5: 10. Population Growth and Contributing Factors
A6: Percent
B8: Net immigration | C8: Births minus deaths | D8: Population growth
A9: 2010 | B9: 0.266 | C9: 0.467 | D9: 0.733
A10: 2011 | B10: 0.241 | C10: 0.435 | D10: 0.676
A11: 2012 | B11: 0.216 | C11: 0.426 | D11: 0.642
A12: 2013 | B12: 0.269 | C12: 0.399 | D12: 0.668
A13: 2014 | B13: 0.52 | C13: 0.403 | D13: 0.923
A14: 2015 | B14: 0.486 | C14: 0.375 | D14: 0.861
A15: 2016 | B15: 0.293 | C15: 0.363 | D15: 0.656
A16: 2017 | B16: 0.35 | C16: 0.311 | D16: 0.66
A17: 2018 | B17: 0.205 | C17: 0.291 | D17: 0.496
A18: 2019 | B18: 0.097 | C18: 0.281 | D18: 0.378
A19: 2020 | B19: 0.256 | C19: 0.055 | D19: 0.311
A20: 2021 | B20: 0.377 | C20: 0.036 | D20: 0.413
A21: 2022 | B21: 0.919 | C21: 0.109 | D21: 1.027 | E21: Projected
A22: 2023 | B22: 1.016 | C22: 0.123 | D22: 1.139
A23: 2024 | B23: 0.652 | C23: 0.134 | D23: 0.786
A24: 2025 | B24: 0.117 | C24: 0.113 | D24: 0.23
A25: 2026 | B25: 0.164 | C25: 0.089 | D25: 0.253
A26: 2027 | B26: 0.198 | C26: 0.061 | D26: 0.259
A27: 2028 | B27: 0.237 | C27: 0.038 | D27: 0.275
A28: 2029 | B28: 0.275 | C28: 0.016 | D28: 0.29
A29: 2030 | B29: 0.306 | C29: -0.006 | D29: 0.3
A30: 2031 | B30: 0.305 | C30: -0.027 | D30: 0.277
A31: 2032 | B31: 0.303 | C31: -0.048 | D31: 0.255
A32: 2033 | B32: 0.305 | C32: -0.069 | D32: 0.237
A33: 2034 | B33: 0.312 | C33: -0.088 | D33: 0.224
... A55: 2056 | B55: 0.338 | C55: -0.339 | D55: 0
A58: Data source: Congressional Budget Office
A59: The population referred to in this table is the Social Security area population, which includes all residents of the 50 U.S. states and the District of Columbia, as well as civilian residents of U.S. territories. It also includes federal civilian employees and members of the U.S. Armed Forces living abroad and their dependents, U.S. citizens living abroad, and noncitizens living abroad who are eligible for Social Security benefits on the basis of their earnings while in the United States.
A62: Back to Table of Contents

Sheet 11. Pop, by Age Group
A1: This file is CBO’s February 2026 publication The Long-Term Budget Outlook Data: 2026 to 2056.
A2: www.cbo.gov/publication/62044
A5: 11. Population, by Age Group
A6: Millions of people
B8: 24 or younger | C8: 25 to 54 | D8: 55 to 64 | E8: 65 or older | F8: Total
A9: 1985 | B9: 95.049 | C9: 98.873 | D9: 22.712 | E9: 28.843 | F9: 245.478
A10: 1986 | B10: 94.762 | C10: 101.048 | D10: 22.615 | E10: 29.422 | F10: 247.848
A11: 1987 | B11: 94.366 | C11: 103.379 | D11: 22.446 | E11: 30.05 | F11: 250.241
A12: 1988 | B12: 94.154 | C12: 105.692 | D12: 22.224 | E12: 30.622 | F12: 252.693
A13: 1989 | B13: 94.101 | C13: 107.976 | D13: 22.003 | E13: 31.128 | F13: 255.208
A14: 1990 | B14: 94.199 | C14: 110.205 | D14: 21.863 | E14: 31.65 | F14: 257.916
A15: 1991 | B15: 94.94 | C15: 112.146 | D15: 21.76 | E15: 32.216 | F15: 261.061
A16: 1992 | B16: 95.753 | C16: 113.971 | D16: 21.68 | E16: 32.772 | F16: 264.176
A17: 1993 | B17: 96.592 | C17: 115.668 | D17: 21.687 | E17: 33.302 | F17: 267.25
A18: 1994 | B18: 97.347 | C18: 117.277 | D18: 21.813 | E18: 33.737 | F18: 270.174
A19: 1995 | B19: 97.932 | C19: 118.992 | D19: 21.953 | E19: 34.131 | F19: 273.008
A20: 1996 | B20: 98.293 | C20: 120.779 | D20: 22.151 | E20: 34.472 | F20: 275.696
... A45: 2021 | B45: 105.431 | C45: 130.953 | D45: 43.578 | E45: 56.726 | F45: 336.687
A46: 2022 | B46: 105.079 | C46: 131.518 | D46: 43.197 | E46: 58.284 | F46: 338.078 | G46: Projected
A47: 2023 | B47: 105.371 | C47: 133.278 | D47: 42.835 | E47: 60.066 | F47: 341.55
A48: 2024 | B48: 105.622 | C48: 135.337 | D48: 42.59 | E48: 61.891 | F48: 345.44
A49: 2025 | B49: 105.411 | C49: 136.639 | D49: 42.373 | E49: 63.733 | F49: 348.156
A50: 2026 | B50: 104.45 | C50: 136.8 | D50: 42.155 | E50: 65.55 | F50: 348.955
A51: 2027 | B51: 103.609 | C51: 137.174 | D51: 41.787 | E51: 67.267 | F51: 349.838
A52: 2028 | B52: 102.802 | C52: 137.795 | D52: 41.243 | E52: 68.903 | F52: 350.742
A53: 2029 | B53: 101.982 | C53: 138.688 | D53: 40.603 | E53: 70.432 | F53: 351.705
A54: 2030 | B54: 101.177 | C54: 139.612 | D54: 40.078 | E54: 71.859 | F54: 352.726
A55: 2031 | B55: 100.385 | C55: 140.606 | D55: 39.748 | E55: 73.047 | F55: 353.786
A56: 2032 | B56: 99.491 | C56: 141.655 | D56: 39.582 | E56: 74.038 | F56: 354.767
A57: 2033 | B57: 98.542 | C57: 142.614 | D57: 39.624 | E57: 74.89 | F57: 355.671
A58: 2034 | B58: 97.638 | C58: 143.497 | D58: 39.656 | E58: 75.722 | F58: 356.513
... A80: 2056 | B80: 87.53 | C80: 141.923 | D80: 47.522 | E80: 87.119 | F80: 364.094
A83: Data source: Congressional Budget Office.
A84: The population referred to in this table is the Social Security area population, which includes all residents of the 50 U.S. states and the District of Columbia, as well as civilian residents of U.S. territories. It also includes federal civilian employees and members of the U.S. Armed Forces living abroad and their dependents, U.S. citizens living abroad, and noncitizens living abroad who are eligible for Social Security benefits on the basis of their earnings while in the United States.
A87: Back to Table of Contents

Sheet 12. Key Econ Variables
A1: This file is CBO’s February 2026 publication The Long-Term Budget Outlook Data: 2026 to 2056.
A2: www.cbo.gov/publication/62044
A5: 12. Average Annual Values for Key Economic Variables That Underlie CBO’s Extended Baseline Projections
A6: Percent
B8: 1996–2025 | C8: 2026–2036 | D8: 2037–2046 | E8: 2047–2056 | F8: Overall, 2026–2056
A9: Growth of GDP
A10: Real GDP | B10: 2.484 | C10: 1.834 | D10: 1.707 | E10: 1.521 | F10: 1.692
A11: Real potential GDPa | B11: 2.443 | C11: 1.965 | D11: 1.707 | E11: 1.521 | F11: 1.738
A12: Potential labor forceb | B12: 0.871 | C12: 0.436 | D12: 0.278 | E12: 0.103 | F12: 0.278
A13: Potential labor force productivityc | B13: 1.558 | C13: 1.522 | D13: 1.424 | E13: 1.416 | F13: 1.456
A14: Real GDP per person | B14: 1.634 | C14: 1.565 | D14: 1.565 | E14: 1.496 | F14: 1.543
A15: Nominal GDP (fiscal years) | B15: 4.739 | C15: 4.004 | D15: 3.743 | E15: 3.557 | F15: 3.775
A16: Labor force growth | B16: 0.891 | C16: 0.409 | D16: 0.263 | E16: 0.122 | F16: 0.269
A17: Labor force participation rated | B17: 64.53 | C17: 62.12 | D17: 61.97 | E17: 62.16 | F17: 62.09
A18: Inflation
A19: Growth of the PCE price index | B19: 2.113 | C19: 2.116 | D19: 1.953 | E19: 1.953 | F19: 2.011
A20: Growth of the CPI-U | B20: 2.529 | C20: 2.357 | D20: 2.261 | E20: 2.268 | F20: 2.297
A21: Growth of the GDP price index | B21: 2.207 | C21: 2.102 | D21: 1.998 | E21: 2.002 | F21: 2.036
A22: Interest Rates
A23: On 10-year Treasury notes
A24: Nominal rate | B24: 3.669 | C24: 4.325 | D24: 4.398 | E24: 4.401 | F24: 4.373
A25: Real rate | B25: 1.129 | C25: 1.968 | D25: 2.137 | E25: 2.132 | F25: 2.075
A26: On all federal debt held by the public (fiscal years)e | B26: 3.684 | C26: 3.79 | D26: 4.099 | E26: 4.164 | F26: 4.01
A29: Data sources: Congressional Budget Office; Bureau of Economic Analysis; Bureau of Labor Statistics; Federal Reserve.
A30: Real values are nominal values that have been adjusted to remove the effects of changes in prices.
A31: The labor force consists of people age 16 or older in the civilian noninstitutionalized population who have jobs or are unemployed (available for work and either seeking work or expecting to be recalled from a temporary layoff). The civilian noninstitutionalized population excludes members of the armed forces on active duty and people in penal or mental institutions, detention facilities, or homes for the elderly or infirm.
A32: CPI-U = consumer price index for all urban consumers; PCE = personal consumption expenditures.
A33: a. An estimate of the amount of real GDP that could be produced if labor and capital were employed at their maximum sustainable rates.
A34: b. An estimate of how big the labor force would be if economic output and other key variables were at their maximum sustainable amounts.
A35: c. The ratio of real potential GDP to the potential labor force. The sum of growth of the potential labor force and growth of potential labor force productivity isequal to growth of real potential GDP.
A36: d. The percentage of the civilian noninstitutionalized population age 16 or older that is in the labor force.
A37: e. The interest rate on all federal debt held by the public equals net interest payments in the current fiscal year divided by debt held by the public at the end of the previous fiscal year.
A40: Back to Table of Contents

Sheet 13. Add'l Econ Variables
A1: This file is CBO’s February 2026 publication The Long-Term Budget Outlook Data: 2026 to 2056.
A2: www.cbo.gov/publication/62044
A5: 13. Average Annual Values for Additional Economic Variables That Underlie CBO’s Extended Baseline Projections
A6: Percent
B8: 1996–2025 | C8: 2026–2036 | D8: 2037–2046 | E8: 2047–2056 | F8: Overall, 2026–2056
A9: Unemployment
A10: Unemployment ratea | B10: 5.524 | C10: 4.327 | D10: 4.066 | E10: 3.92 | F10: 4.112
A11: Noncyclical rate of unemploymentb | B11: 4.852 | C11: 4.282 | D11: 4.066 | E11: 3.92 | F11: 4.096
A12: Growth of average weekly hours worked | B12: -0.116 | C12: 0.089 | D12: -0.017 | E12: -0.015 | F12: 0.021
A13: Growth of total hours worked | B13: 0.742 | C13: 0.478 | D13: 0.27 | E13: 0.117 | F13: 0.295
A14: Earnings as a share of compensation | B14: 81.478 | C14: 81.847 | D14: 81.329 | E14: 80.984 | F14: 81.401
A15: Growth of real earnings per worker | B15: 1.182 | C15: 1.179 | D15: 1.108 | E15: 1.058 | F15: 1.117
A16: Growth of total factor productivityc | B16: 1.281 | C16: 1.042 | D16: 1.14 | E16: 1.098 | F16: 1.092
A17: Growth of labor productivity (real GDP per hour worked) | B17: 1.728 | C17: 1.349 | D17: 1.432 | E17: 1.401 | F17: 1.393
A20: Data sources: Congressional Budget Office; Bureau of Labor Statistics.
A22: Real values are nominal values that have been adjusted to remove the effects of changes in prices.
A24: * = between -0.05 percent and 0.05 percent.
A25: a. The percentage of people in the labor force who are not working but are available for work and are either seeking work or expecting to be recalled from a temporary layoff.
A26: b. The rate of unemployment resulting from all sources except changes in aggregate demand.
A27: c. Total factor productivity is the average real output per unit of combined labor and capital services.
A30: Back to Table of Contents

Sheet 14. GDP Growth
A1: This file is CBO’s February 2026 publication The Long-Term Budget Outlook Data: 2026 to 2056.
A2: www.cbo.gov/publication/62044
A5: 14. Average Annual Growth of Real Potential GDP and Its Components
A6: Percent
B8: Potential labor force | C8: Potential labor force productivity | D8: Real potential GDP
A9: 1996–2025 | B9: 0.871 | C9: 1.558 | D9: 2.443
A10: 2026–2036 | B10: 0.436 | C10: 1.522 | D10: 1.965
A11: 2037–2046 | B11: 0.278 | C11: 1.424 | D11: 1.707
A12: 2047–2056 | B12: 0.103 | C12: 1.416 | D12: 1.521
A15: Data source: Congressional Budget Office.
A16: Real values are nominal values that have been adjusted to remove the effects of changes in prices.
A17: Real potential GDP is CBO’s estimate of the amount of real GDP that could be produced if labor and capital were employed at their maximum sustainable rates. Its growth is the sum of the growth of the potential labor force and of potential labor force productivity. The potential labor force is CBO’s estimate of how big the labor force would be if economic output and other key variables were at their maximum sustainable amounts. Potential labor force productivity is a measure of the maximum sustainable output per worker, calculated by dividing real potential GDP by the potential labor force.
A18: The values are average annual growth rates over the specified periods.Those rates are calculated using calendar year data.
A21: Back to Table of Contents

Sheet 15. Interest Rates
A1: This file is CBO’s February 2026 publication The Long-Term Budget Outlook Data: 2026 to 2056.
A2: www.cbo.gov/publication/62044
A5: 15. Average Interest Rates on Federal Debt and on 10-year Treasury Notes
A6: Percent
B8: 10-year Treasury note rate | C8: Average rate on federal debt
A9: 1996 | B9: 6.326 | C9: 6.688
A10: 1997 | B10: 6.462 | C10: 6.534
A11: 1998 | B11: 5.573 | C11: 6.392
A12: 1999 | B12: 5.269 | C12: 6.174
A13: 2000 | B13: 6.173 | C13: 6.138
A14: 2001 | B14: 5.217 | C14: 6.046
A15: 2002 | B15: 4.802 | C15: 5.1497
A16: 2003 | B16: 3.945 | C16: 4.324
A17: 2004 | B17: 4.303 | C17: 4.095
A18: 2005 | B18: 4.211 | C18: 4.283
A19: 2006 | B19: 4.757 | C19: 4.935
A20: 2007 | B20: 4.722 | C20: 4.91
... A38: 2025 | B38: 4.338 | C38: 3.44
A39: 2026 | B39: 4.098 | C39: 3.443 | D39: Projected
A40: 2027 | B40: 4.235 | C40: 3.451
A41: 2028 | B41: 4.295 | C41: 3.581
A42: 2029 | B42: 4.324 | C42: 3.67
A43: 2030 | B43: 4.34 | C43: 3.758
A44: 2031 | B44: 4.3499 | C44: 3.844
A45: 2032 | B45: 4.358 | C45: 3.928
A46: 2033 | B46: 4.365 | C46: 3.972
A47: 2034 | B47: 4.373 | C47: 3.996
A48: 2035 | B48: 4.38 | C48: 4.007
A49: 2036 | B49: 4.387 | C49: 4.038
A50: 2037 | B50: 4.393 | C50: 4.046
A51: 2038 | B51: 4.398 | C51: 4.057
... A69: 2056 | B69: 4.43 | C69: 4.176
A72: Data sources: Congressional Budget Office; Federal Reserve.
A73: Data are for fiscal years. The average interest rate on all federal debt held by the public equals net interest payments in the current year divided by debt held by the public at the end of the previous year.
A76: Back to Table of Contents

Sheet 16. 2025&2026 Econ Proj
A1: This file is CBO’s February 2026 publication The Long-Term Budget Outlook Data: 2026 to 2056.
A2: www.cbo.gov/publication/62044
A5: 16. CBO’s 2025 and 2026 Projections of Selected Economic Variables
A6: Percent
B8: Growth of real GDPa | E8: CPI-U inflation | H8: Interest rate on 10-year Treasury notes
B9: 2025 projections | C9: 2026 projections | E9: 2025 projections | F9: 2026 projections | H9: 2025 projections | I9: 2026 projections
A10: 2025 | B10: 2.124 | C10: 2.02 | E10: 2.235 | F10: 2.767 | H10: 4.093 | I10: 4.288
A11: 2026 | B11: 1.827 | C11: 2.364 | E11: 2.441 | F11: 2.924 | H11: 3.935 | I11: 4.127
A12: 2027 | B12: 1.763 | C12: 1.861 | E12: 2.315 | F12: 2.547 | H12: 3.914 | I12: 4.254
A13: 2028 | B13: 1.744 | C13: 1.805 | E13: 2.257 | F13: 2.361 | H13: 3.894 | I13: 4.303
A14: 2029 | B14: 1.786 | C14: 1.754 | E14: 2.242 | F14: 2.288 | H14: 3.871 | I14: 4.329
A15: 2030 | B15: 1.821 | C15: 1.783 | E15: 2.237 | F15: 2.263 | H15: 3.85 | I15: 4.342
A16: 2031 | B16: 1.822 | C16: 1.776 | E16: 2.236 | F16: 2.258 | H16: 3.836 | I16: 4.351
A17: 2032 | B17: 1.842 | C17: 1.76 | E17: 2.239 | F17: 2.257 | H17: 3.826 | I17: 4.359
A18: 2033 | B18: 1.826 | C18: 1.767 | E18: 2.242 | F18: 2.256 | H18: 3.815 | I18: 4.366
A19: 2034 | B19: 1.797 | C19: 1.769 | E19: 2.246 | F19: 2.256 | H19: 3.797 | I19: 4.374
A20: 2035 | B20: 1.76 | C20: 1.772 | E20: 2.25 | F20: 2.257 | H20: 3.772 | I20: 4.381
A21: 2036 | B21: 1.724 | C21: 1.766 | E21: 2.253 | F21: 2.257 | H21: 3.747 | I21: 4.388
... A40: 2055 | B40: 1.356 | C40: 1.483 | E40: 2.276 | F40: 2.27 | H40: 3.784 | I40: 4.423
A43: Data source: Congressional Budget Office
A45: CPI-U = consumer price index for all urban consumers.
A46: a. Real GDP is nominal GDP that has been adjusted to remove the effects of changes in prices.
A49: Back to Table of Contents

Sheet 17. 2025&2026 Lbr Force Proj
A1: This file is CBO’s February 2026 publication The Long-Term Budget Outlook Data: 2026 to 2056.
A2: www.cbo.gov/publication/62044
A5: 17. CBO’s 2025 and 2026 Projections of the Labor Force
A6: Percent
B8: Growth of the labor force | E8: Labor force participation rate
B9: 2025 projections | C9: 2026 projections | E9: 2025 projections | F9: 2026 projections
A10: 2000 | B10: 2.3 | C10: 1.423 | E10: 67.08 | F10: 67.06
A11: 2001 | B11: 0.829 | C11: 0.817 | E11: 66.84 | F11: 66.77
A12: 2002 | B12: 0.756 | C12: 0.663 | E12: 66.58 | F12: 66.42
A13: 2003 | B13: 1.134 | C13: 0.503 | E13: 66.24 | F13: 66.02
A14: 2004 | B14: 0.6 | C14: 0.756 | E14: 65.98 | F14: 65.76
A15: 2005 | B15: 1.295 | C15: 1.266 | E15: 66.03 | F15: 65.79
A16: 2006 | B16: 1.419 | C16: 1.464 | E16: 66.17 | F16: 65.91
A17: 2007 | B17: 1.132 | C17: 0.954 | E17: 66.04 | F17: 65.72
A18: 2008 | B18: 0.782 | C18: 1.101 | E18: 66.01 | F18: 65.69
A19: 2009 | B19: -0.086 | C19: 0.074 | E19: 65.39 | F19: 65.05
A20: 2010 | B20: -0.196 | C20: -0.011 | E20: 64.7 | F20: 64.39
A21: 2011 | B21: -0.169 | C21: 0.221 | E21: 64.11 | F21: 63.89
... A35: 2025 | B35: 1.438 | C35: 0.471 | E35: 62.65 | F35: 62.55
A36: 2026 | B36: 1.589 | C36: 0.498 | E36: 62.42 | F36: 62.45 | G36: Projected
A37: 2027 | B37: 0.364 | C37: 0.4 | E37: 62.11 | F37: 62.38
A38: 2028 | B38: 0.349 | C38: 0.411 | E38: 61.88 | F38: 62.3
A39: 2029 | B39: 0.389 | C39: 0.43 | E39: 61.73 | F39: 62.23
A40: 2030 | B40: 0.419 | C40: 0.457 | E40: 61.63 | F40: 62.16
A41: 2031 | B41: 0.437 | C41: 0.461 | E41: 61.55 | F41: 62.09
A42: 2032 | B42: 0.428 | C42: 0.432 | E42: 61.48 | F42: 62.03
A43: 2033 | B43: 0.348 | C43: 0.393 | E43: 61.43 | F43: 61.97
A44: 2034 | B44: 0.347 | C44: 0.356 | E44: 61.39 | F44: 61.93
A45: 2035 | B45: 0.33 | C45: 0.337 | E45: 61.37 | F45: 61.9
A46: 2036 | B46: 0.313 | C46: 0.321 | E46: 61.36 | F46: 61.88
A47: 2037 | B47: 0.297 | C47: 0.309 | E47: 61.37 | F47: 61.88
A48: 2038 | B48: 0.29 | C48: 0.314 | E48: 61.37 | F48: 61.89
... A65: 2055 | B65: 0.052 | C65: 0.085 | E65: 61.22 | F65: 62.15
A68: Data sources: Congressional Budget Office; Bureau of Labor Statistics.
A69: The labor force participation rate is the percentage of the civilian noninstitutionalized population age 16 or older that is in the labor force. The labor force consists of people age 16 or older in the civilian noninstitutionalized population who have jobs or are unemployed (available for work and either seeking work or expecting to be recalled from a temporary layoff). The civilian noninstitutionalized population excludes members of the armed forces on active duty and people in penal or mental institutions, detention facilities, or homes for the elderly or infirm.
A72: Back to Table of Contents

Sheet 18. 2025&2026 Real GDP Proj
A1: This file is CBO’s February 2026 publication The Long-Term Budget Outlook Data: 2026 to 2056.
A2: www.cbo.gov/publication/62044
A5: 18. CBO’s 2025 and 2026 Projections of Real Potential GDP
A6: Percent
B8: 2025 projections | C8: 2026 projections
A9: 2025 | B9: 2.303 | C9: 2.438
A10: 2026 | B10: 2.286 | C10: 2.215
A11: 2027 | B11: 2.219 | C11: 2.149
A12: 2028 | B12: 2.156 | C12: 2.101
A13: 2029 | B13: 2.097 | C13: 2.039
A14: 2030 | B14: 2.012 | C14: 2.02
A15: 2031 | B15: 1.939 | C15: 1.972
A16: 2032 | B16: 1.883 | C16: 1.902
A17: 2033 | B17: 1.829 | C17: 1.852
A18: 2034 | B18: 1.797 | C18: 1.816
A19: 2035 | B19: 1.76 | C19: 1.784
A20: 2036 | B20: 1.724 | C20: 1.767
... A39: 2055 | B39: 1.356 | C39: 1.483
A42: Data source: Congressional Budget Office.
A43: Real values are nominal values that have been adjusted to remove the effects of changes in prices.
A44: Real potential GDP is CBO’s estimate of the amount of real GDP that could be produced if labor and capital were employed at their maximum sustainable rates. Its growth is the sum of the growth of the potential labor force and of potential labor force productivity. The potential labor force is CBO’s estimate of how big the labor force would be if economic output and other key variables were at their maximum sustainable amounts. Potential labor force productivity is a measure of the maximum sustainable output per worker, calculated by dividing real potential GDP by the potential labor force.
A47: Back to Table of Contents

Sheet 19. 2025&2026 Int Rate Proj
A1: This file is CBO’s February 2026 publication The Long-Term Budget Outlook Data: 2026 to 2056.
A2: www.cbo.gov/publication/62044
A5: 19. CBO’s 2025 and 2026 Projections of Interest Rates on 10-Year Treasury Notes
A6: Percent
B8: 10-year Treasury note rate
B9: 2025 projections | C9: 2026 projections
A10: 1996 | B10: 6.438 | C10: 6.438
A11: 1997 | B11: 6.353 | C11: 6.353
A12: 1998 | B12: 5.264 | C12: 5.264
A13: 1999 | B13: 5.637 | C13: 5.637
A14: 2000 | B14: 6.029 | C14: 6.029
A15: 2001 | B15: 5.018 | C15: 5.018
A16: 2002 | B16: 4.611 | C16: 4.611
A17: 2003 | B17: 4.015 | C17: 4.015
A18: 2004 | B18: 4.274 | C18: 4.274
A19: 2005 | B19: 4.29 | C19: 4.29
A20: 2006 | B20: 4.792 | C20: 4.792
A21: 2007 | B21: 4.629 | C21: 4.629
... A38: 2024 | B38: 4.188 | C38: 4.208
A39: 2025 | B39: 4.094 | C39: 4.288 | D39: Projected
A40: 2026 | B40: 3.936 | C40: 4.127
A41: 2027 | B41: 3.915 | C41: 4.255
A42: 2028 | B42: 3.895 | C42: 4.304
A43: 2029 | B43: 3.872 | C43: 4.329
A44: 2030 | B44: 3.851 | C44: 4.343
A45: 2031 | B45: 3.837 | C45: 4.352
A46: 2032 | B46: 3.827 | C46: 4.36
A47: 2033 | B47: 3.815 | C47: 4.367
A48: 2034 | B48: 3.797 | C48: 4.375
A49: 2035 | B49: 3.772 | C49: 4.382
A50: 2036 | B50: 3.748 | C50: 4.388
A51: 2037 | B51: 3.73 | C51: 4.394
... A69: 2055 | B69: 3.785 | C69: 4.423
A72: Data source: Congressional Budget Office.
A75: Back to Table of Contents

Sheet 20. 2025&2026 Proj, Select Yrs
A1: This file is CBO’s February 2026 publication The Long-Term Budget Outlook Data: 2026 to 2056.
A2: www.cbo.gov/publication/62044
A5: 20. CBO’s 2025 and 2026 Projections of Revenues, Outlays, Deficits, and Federal Debt Held by the Public in Selected Years
A6: Percentage of GDP
B8: 2026 | C8: 2037 | D8: 2047 | E8: 2055
A9: Revenues
A10: Individual income taxes
A11: 2025 projections | B11: 9.471 | C11: 10.172 | D11: 10.619 | E11: 10.929
A12: 2026 projections | B12: 8.624 | C12: 9.154 | D12: 9.676 | E12: 10.059
A13: Payroll taxes
A14: 2025 projections | B14: 5.872 | C14: 5.938 | D14: 5.925 | E14: 5.909
A15: 2026 projections | B15: 5.722 | C15: 5.703 | D15: 5.681 | E15: 5.662
A16: Corporate income taxes
A17: 2025 projections | B17: 1.58 | C17: 1.179 | D17: 1.221 | E17: 1.218
A18: 2026 projections | B18: 1.266 | C18: 1.229 | D18: 1.288 | E18: 1.304
A19: Customs dutiesa
A20: 2025 projections | B20: 0.267 | C20: 0.232 | D20: 0.201 | E20: 0.182
A21: 2026 projections | B21: 1.311 | C21: 0.851 | D21: 0.741 | E21: 0.68
A22: Otherb
A23: 2025 projections | B23: 0.615 | C23: 0.921 | D23: 1.025 | E23: 1.083
A24: 2026 projections | B24: 0.617 | C24: 0.89 | D24: 0.989 | E24: 1.036
A25: Total revenues
A26: 2025 projections | B26: 17.805 | C26: 18.442 | D26: 18.991 | E26: 19.322
A27: 2026 projections | B27: 17.541 | C27: 17.826 | D27: 18.374 | E27: 18.741
A28: Outlays
A29: Mandatory
A30: Social Security
A31: 2025 projections | B31: 5.31 | C31: 5.959 | D31: 5.878 | E31: 6.06
A32: 2026 projections | B32: 5.222 | C32: 5.869 | D32: 5.789 | E32: 5.968
A33: Major health care programsc
A34: 2025 projections | B34: 5.844 | C34: 6.915 | D34: 7.733 | E34: 8.101
A35: 2026 projections | B35: 5.982 | C35: 6.758 | D35: 7.624 | E35: 8.04
A36: Otherd
A37: 2025 projections | B37: 2.841 | C37: 2.342 | D37: 2.09 | E37: 1.917
A38: 2026 projections | B38: 2.994 | C38: 2.484 | D38: 2.367 | E38: 2.294
A39: Subtotal, mandatory
A40: 2025 projections | B40: 13.995 | C40: 15.216 | D40: 15.701 | E40: 16.077
A41: 2026 projections | B41: 14.198 | C41: 15.111 | D41: 15.78 | E41: 16.302
A42: Discretionary
A43: 2025 projections | B43: 6.053 | C43: 5.16 | D43: 5.11 | E43: 5.11
...

Sheet 21. 2025&2026 Def & Debt
A1: This file is CBO’s February 2026 publication The Long-Term Budget Outlook Data: 2026 to 2056.
A2: www.cbo.gov/publication/62044
A5: 21. CBO’s 2025 and 2026 Projections of Deficits and Federal Debt Held by the Public
A6: Percentage of GDP
B8: Primary deficit | E8: Total deficit | H8: Federal debt held by the public
B9: 2025 projections | C9: 2026 projections | E9: 2025 projections | F9: 2026 projections | H9: 2025 projections | I9: 2026 projections
A10: 2025 | B10: 3.03 | C10: 2.656 | E10: 6.189 | F10: 5.847 | H10: 99.889 | I10: 99.375
A11: 2026 | B11: 2.243 | C11: 2.551 | E11: 5.466 | F11: 5.807 | H11: 101.727 | I11: 100.605
A12: 2027 | B12: 1.88 | C12: 2.34 | E12: 5.185 | F12: 5.665 | H12: 103.375 | I12: 102.069
A13: 2028 | B13: 1.867 | C13: 2.13 | E13: 5.316 | F13: 5.643 | H13: 105.438 | I13: 104.116
A14: 2029 | B14: 2.303 | C14: 2.274 | E14: 5.861 | F14: 5.952 | H14: 107.228 | I14: 105.811
A15: 2030 | B15: 2.232 | C15: 2.056 | E15: 5.879 | F15: 5.886 | H15: 109.216 | I15: 107.726
A16: 2031 | B16: 2.159 | C16: 1.9 | E16: 5.908 | F16: 5.889 | H16: 111.114 | I16: 109.573
A17: 2032 | B17: 2.182 | C17: 1.909 | E17: 6.039 | F17: 6.057 | H17: 113.042 | I17: 111.535
A18: 2033 | B18: 2.15 | C18: 1.987 | E18: 6.086 | F18: 6.256 | H18: 115.25 | I18: 113.992
A19: 2034 | B19: 2.109 | C19: 2.081 | E19: 6.109 | F19: 6.47 | H19: 117.068 | I19: 116.186
A20: 2035 | B20: 2.085 | C20: 2.084 | E20: 6.142 | F20: 6.57 | H20: 118.48 | I20: 117.977
A21: 2036 | B21: 2.015 | C21: 2.079 | E21: 6.113 | F21: 6.669 | H21: 120.256 | I21: 120.209
... A40: 2055 | B40: 1.865 | C40: 2.201 | E40: 7.289 | F40: 8.991 | H40: 156.327 | I40: 171.785
A43: Data source: Congressional Budget Office.
A44: In this figure, deficits were calculated by subtracting revenues from outlays; thus, positive values indicate deficits.
A45: Primary deficits exclude net outlays for interest.
A48: Back to Table of Contents

Sheet 22. 2025&2026 Outlay Proj
A1: This file is CBO’s February 2026 publication The Long-Term Budget Outlook Data: 2026 to 2056.
A2: www.cbo.gov/publication/62044
A5: 22. CBO’s 2025 and 2026 Projections of Outlays
A6: Percentage of GDP
B8: Noninterest | E8: Net interest
B9: 2025 projections | C9: 2026 projections | E9: 2025 projections | F9: 2026 projections
A10: 2025 | B10: 20.161 | C10: 19.914 | E10: 3.16 | F10: 3.195
A11: 2026 | B11: 20.048 | C11: 20.092 | E11: 3.223 | F11: 3.257
A12: 2027 | B12: 20.12 | C12: 20.005 | E12: 3.305 | F12: 3.325
A13: 2028 | B13: 19.958 | C13: 19.644 | E13: 3.449 | F13: 3.513
A14: 2029 | B14: 20.249 | C14: 19.824 | E14: 3.559 | F14: 3.678
A15: 2030 | B15: 20.228 | C15: 19.694 | E15: 3.648 | F15: 3.829
A16: 2031 | B16: 20.242 | C16: 19.599 | E16: 3.749 | F16: 3.989
A17: 2032 | B17: 20.287 | C17: 19.611 | E17: 3.857 | F17: 4.147
A18: 2033 | B18: 20.313 | C18: 19.672 | E18: 3.936 | F18: 4.269
A19: 2034 | B19: 20.318 | C19: 19.762 | E19: 4.001 | F19: 4.389
A20: 2035 | B20: 20.364 | C20: 19.795 | E20: 4.057 | F20: 4.486
A21: 2036 | B21: 20.366 | C21: 19.849 | E21: 4.098 | F21: 4.591
... A40: 2055 | B40: 21.187 | C40: 20.943 | E40: 5.424 | F40: 6.79
A43: Data source: Congressional Budget Office
A46: Back to Table of Contents

Sheet 23. 2025&2026 Rev Proj
A1: This file is CBO’s February 2026 publication The Long-Term Budget Outlook Data: 2026 to 2056.
A2: www.cbo.gov/publication/62044
A5: 23. CBO’s 2025 and 2026 Projections of Revenues
A6: Percentage of GDP
B8: 2025 projections | C8: 2026 projections
A9: 2025 | B9: 17.132 | C9: 17.241
A10: 2026 | B10: 17.805 | C10: 17.541
A11: 2027 | B11: 18.24 | C11: 17.665
A12: 2028 | B12: 18.091 | C12: 17.514
A13: 2029 | B13: 17.947 | C13: 17.55
A14: 2030 | B14: 17.996 | C14: 17.638
A15: 2031 | B15: 18.084 | C15: 17.699
A16: 2032 | B16: 18.104 | C16: 17.702
A17: 2033 | B17: 18.163 | C17: 17.685
A18: 2034 | B18: 18.21 | C18: 17.681
A19: 2035 | B19: 18.28 | C19: 17.711
A20: 2036 | B20: 18.352 | C20: 17.77
... A39: 2055 | B39: 19.322 | C39: 18.741
A42: Data source: Congressional Budget Office.
A45: Back to Table of Contents
